<?xml version='1.0'?>
<robot xmlns:xacro="http://www.ros.org/wiki/xacro">
<xacro:include filename="$(find lib_omni_mobile)/urdf/roller_wheel.urdf.xacro"/>
<xacro:macro name="rim" params="name parent xyz rpy">
    <link name="${name}">
        <inertial>
            <mass value="0.10"/>
            <inertia ixx="7.6e-5" ixy="0.0" ixz="0.0" iyy="7.6e-5" iyz="0.0" izz="0.000125"/>
        </inertial>
        <visual>
            <geometry>
                <cylinder radius="0.0435" length="0.029"/>
            </geometry>
            <material name="black"/>
        </visual>
        <collision>
            <geometry>
                <cylinder radius="0.0435" length="0.029"/>
            </geometry>
            <material name="black"/>
        </collision>
    </link>
    <joint name="joint_${name}" type="continuous">
        <parent link="${parent}"/>
        <child link="${name}"/>
        <axis xyz = "0 0 1"/>
        <origin xyz = "${xyz}" rpy = "${rpy}" />
        <limit effort="1000" velocity="3140"/>
    </joint>

    <xacro:roller name="8" parent="${name}"  xyz="0.053 0 0.0095" rpy="1.57 0 0"/>
	<xacro:roller name="7" parent="${name}"  xyz="0.048966 0.020282 -0.0095" rpy="1.57 0 0.3927"/>
	<xacro:roller name="6" parent="${name}"  xyz="0.037477 0.037477 0.0095" rpy="1.57 0 0.7854"/>
	<xacro:roller name="5" parent="${name}"  xyz="0.020282 0.048966 -0.0095" rpy="1.57 0 1.1781"/>
	<xacro:roller name="4" parent="${name}"  xyz="0 0.053 0.0095" rpy="1.57 0 1.5708"/>
	<xacro:roller name="3" parent="${name}"  xyz="-0.020282 0.048966 -0.0095" rpy="1.57 0 1.9635"/>
	<xacro:roller name="2" parent="${name}"  xyz="-0.037477 0.037477 0.0095" rpy="1.57 0 2.3562"/>
	<xacro:roller name="1" parent="${name}"  xyz="-0.048966 0.020282 -0.0095" rpy="1.57 0 2.7489"/>
	<xacro:roller name="16" parent="${name}" xyz="-0.053 0 0.0095" rpy="1.57 0 3.1416"/>
	<xacro:roller name="15" parent="${name}" xyz="-0.048966 -0.020282 -0.0095" rpy="1.57 0 -2.7489"/>
	<xacro:roller name="14" parent="${name}" xyz="-0.037477 -0.037477 0.0095" rpy="1.57 0 -2.3562"/>
	<xacro:roller name="13" parent="${name}" xyz="-0.020282 -0.048966 -0.0095" rpy="1.57 0 -1.9635"/>
	<xacro:roller name="12" parent="${name}" xyz="0 -0.053 0.0095" rpy="1.57 0 -1.5708"/>
	<xacro:roller name="11" parent="${name}" xyz="0.020282 -0.048966 -0.0095" rpy="1.57 0 -1.1781"/>
	<xacro:roller name="10" parent="${name}" xyz="0.037477 -0.037477 0.0095" rpy="1.57 0 -0.7854"/>
	<xacro:roller name="9" parent="${name}" xyz="0.048966 -0.020282 -0.0095" rpy="1.57 0 -0.3927"/>

    <transmission name="${name}_tran">
        <type>transmission_interface/SimpleTransmission</type>
        <joint name="joint_${name}">
            <hardwareInterface>hardware_interface/EffortJointInterface</hardwareInterface>
        </joint>
        <actuator name="${name}_motor">
            <hardwareInterface>hardware_interface/EffortJointInterface</hardwareInterface>
            <mechanicalReduction>1</mechanicalReduction>
        </actuator>
    </transmission>

</xacro:macro>
</robot>
